Workbook

Sheet Assumptions
A1: BuildItToday.ai — Model Assumptions
A2: Blue = you can change it. Yellow = confirm this from your own invoices. Black = calculated.
A4: COST TO FIND AND BUILD ONE LEAD
A5: DataSkip lookup, per lead checked | B5: 0.04 | C5: $ | D5: Your figure, 10 Sep 2026
A6: …of which return an email address | B6: 0.777 | C6: % | D6: MEASURED: 818 emails from 1,053 checks
A7: …of which return a mailing address | B7: 0.831 | C7: % | D7: MEASURED: 875 addresses from 1,053 checks
A8: Three photographs | B8: 0.13 | C8: $ | D8: MEASURED across 27 builds
A9: Four-second hero video | B9: 0.14 | C9: $ | D9: MEASURED across 27 builds
A10: Website copy + HTML build | B10: 0.23 | C10: $ | D10: ESTIMATED — not separately instrumented
A11: Site build, total | B11: =B8+B9+B10 | C11: $ | D11: Media measured at $0.2705 mean, range $0.19–$0.32
A12: Email send | B12: 0 | C12: $ | D12: Templates, no model call. Verified in code.
A13: Postcard, printed and mailed | B13: 0.75 | C13: $ | D13: Lob list price, per PROJECT.md — not yet verified by an invoice
A14: Cost per emailable lead found + built | B14: =B5/B6+B11 | C14: $ | D14: DataSkip is paid on every check, but only 77.7% yield an email
A15: Cost per postcard lead found + built + mailed | B15: =B5/B7+B11+B13 | C15: $ | D15: Same, plus print and postage
A17: OVERHEADS
A18: Hosting, database, email, domain — monthly | B18: 0 | C18: $/mo | D18: CONFIRM: Supabase + Vercel + Resend + domain. $0 if all free tiers, ~$65 if all paid.
A19: Stripe — percentage | B19: 0.029 | C19: % | D19: Stripe US standard
A20: Stripe — fixed, per transaction | B20: 0.3 | C20: $ | D20: Stripe US standard
A22: WHAT YOU CHARGE
B23: Setup | C23: Monthly
A24: Starter | B24: 750 | C24: 50 | D24: From frontend/src/lib/pricing.ts
A25: Professional | B25: 1500 | C25: 99
A26: Signature | B26: 3500 | C26: 199
A28: Mix — Starter | B28: 0.7 | C28: % | D28: ASSUMPTION. No sales yet, so this is a guess.
A29: Mix — Professional | B29: 0.25 | C29: % | D29: ASSUMPTION
A30: Mix — Signature | B30: 0.05 | C30: % | D30: ASSUMPTION
A31: Mix check — must equal 100% | B31: =B28+B29+B30 | C31: % | D31: If this is not 100%, the revenue lines are wrong
A32: Weighted setup fee | B32: =B24*B28+B25*B29+B26*B30 | C32: $ | D32: Blended across the mix above
A33: Weighted monthly fee | B33: =C24*B28+C25*B29+C26*B30 | C33: $ | D33: Blended across the mix above
A35: MONTHLY VOLUME — the levers you actually control
A36: New leads scraped per month | B36: 18000 | C36: leads | D36: MEASURED: 36,102 in Aug, 18,152 in Sep (part month)
A37: …share that qualify | B37: 0.6 | C37: % | D37: MEASURED: 32,540 of 54,254
A38: DataSkip lookups per month | B38: 1000 | C38: leads | D38: MEASURED to date: 1,053 in Aug, 0 in Sep. THIS IS THE MAIN LEVER.
A39: Email addresses found | B39: =B38*B6 | C39: leads | D39: Lookups × hit rate
A40: Mailing addresses found | B40: =B38*B7 | C40: leads | D40: Lookups × hit rate
A41: Sites built | B41: =B39 | C41: sites | D41: One per emailable lead. Capacity today is 10/day = ~300/mo.
A42: Emails sent | B42: =B39 | C42: sends | D42: Everyone with an email and an approved site
A43: …share also sent a postcard | B43: 0 | C43: % | D43: 0% = email only. Set to 1.00 to mail every lead that has an address.
A44: Postcards sent | B44: =B40*B43 | C44: cards | D44: Mailing addresses × the share above
A46: CONVERSION — the numbers nobody knows yet
...

Sheet What we know
A1: Measured facts, read from the live database on 10 Sep 2026
A2: Nothing on this sheet is a projection. Every figure is a count from the database.
A4: THE FUNNEL, ALL TIME
A5: Leads scraped | B5: 54254 | C5: 36,102 in August, 18,152 in September
A6: Qualified as a target | B6: 32540 | C6: 60.0% of everything scraped
A7: Checked with DataSkip | B7: 1053 | C7: 3.2% of qualified leads. The rest have never been looked up.
A8: …that returned an email address | B8: 818 | C8: 77.7% hit rate
A9: …that returned a mailing address | B9: 875 | C9: 83.1% hit rate
A10: Qualified but NEVER checked | B10: 31487 | C10: Your unworked inventory. At $0.04 each, $1,259 to check all of them.
A11: WHAT WAS ACTUALLY BUILT AND SENT
A12: Demo sites built | B12: 63 | C12: Each with its own photography and hero video
A13: Sites approved by the quality gate | B13: 52
A14: Real emails sent to real businesses | B14: 47 | C14: Excludes rehearsals sent to your own inbox
A15: Postcards sent | B15: 0 | C15: The channel has never been tried
A16: Paying customers | B16: 0 | C16: The customers table is empty
A17: MONEY
A18: OpenRouter credit consumed | B18: -283.51 | C18: Of $288.00 granted
A19: OpenRouter credit remaining | B19: 4.49 | C19: About 9 more sites at $0.50, then building stops
A20: Revenue | B20: 0
A21: WHAT 47 SENDS CAN TELL YOU
A22: Observed conversions | B22: 0 of 47
A23: 95% upper bound on the true rate | B23: 6.4% | C23: Rule of three: with 0 events in 47 trials, 3/47. The true rate could be anything from 0% to 6.4%.
A24: Verdict | B24: Not enough data | C24: This sample cannot separate 'the price is wrong' from 'we have not sent enough'.
A25: Complication | B25: Buy button was broken | C25: On all 55 sites it closed the popup and went nowhere until 9 Sep. Nobody could have paid.
A26: Complication | B26: All engagement was internal | C26: Every view and click traced back to test emails in your own inbox or Telegram links.

Sheet Monthly P&L
A1: Monthly P&L — 24 months
A2: Every figure is a formula driven by the Assumptions sheet. Change an input there and this whole sheet moves.
A4: Month | B4: Oct 2026 | C4: Nov 2026 | D4: Dec 2026 | E4: Jan 2027 | F4: Feb 2027 | G4: Mar 2027 | H4: Apr 2027 | I4: May 2027 | J4: Jun 2027 | K4: Jul 2027 | L4: Aug 2027 | M4: Sep 2027 | N4: Oct 2027 | O4: Nov 2027 | P4: Dec 2027 | Q4: Jan 2028 | R4: Feb 2028 | S4: Mar 2028 | T4: Apr 2028 | U4: May 2028 | V4: Jun 2028 | W4: Jul 2028 | X4: Aug 2028 | Y4: Sep 2028
A6: VOLUME
A7: New leads scraped | B7: ='Assumptions'!$B$36 | C7: ='Assumptions'!$B$36 | D7: ='Assumptions'!$B$36 | E7: ='Assumptions'!$B$36 | F7: ='Assumptions'!$B$36 | G7: ='Assumptions'!$B$36 | H7: ='Assumptions'!$B$36 | I7: ='Assumptions'!$B$36 | ... Y7: ='Assumptions'!$B$36
A8: DataSkip lookups | B8: ='Assumptions'!$B$38 | C8: ='Assumptions'!$B$38 | D8: ='Assumptions'!$B$38 | E8: ='Assumptions'!$B$38 | F8: ='Assumptions'!$B$38 | G8: ='Assumptions'!$B$38 | H8: ='Assumptions'!$B$38 | I8: ='Assumptions'!$B$38 | ... Y8: ='Assumptions'!$B$38
A9: Email addresses found | B9: =B8*'Assumptions'!$B$6 | C9: =C8*'Assumptions'!$B$6 | D9: =D8*'Assumptions'!$B$6 | E9: =E8*'Assumptions'!$B$6 | F9: =F8*'Assumptions'!$B$6 | G9: =G8*'Assumptions'!$B$6 | H9: =H8*'Assumptions'!$B$6 | I9: =I8*'Assumptions'!$B$6 | ... Y9: =Y8*'Assumptions'!$B$6
A10: Mailing addresses found | B10: =B8*'Assumptions'!$B$7 | C10: =C8*'Assumptions'!$B$7 | D10: =D8*'Assumptions'!$B$7 | E10: =E8*'Assumptions'!$B$7 | F10: =F8*'Assumptions'!$B$7 | G10: =G8*'Assumptions'!$B$7 | H10: =H8*'Assumptions'!$B$7 | I10: =I8*'Assumptions'!$B$7 | ... Y10: =Y8*'Assumptions'!$B$7
A11: Sites built | B11: =B9 | C11: =C9 | D11: =D9 | E11: =E9 | F11: =F9 | G11: =G9 | H11: =H9 | I11: =I9 | ... Y11: =Y9
A12: Emails sent | B12: =B9 | C12: =C9 | D12: =D9 | E12: =E9 | F12: =F9 | G12: =G9 | H12: =H9 | I12: =I9 | ... Y12: =Y9
A13: Postcards sent | B13: =B10*'Assumptions'!$B$43 | C13: =C10*'Assumptions'!$B$43 | D13: =D10*'Assumptions'!$B$43 | E13: =E10*'Assumptions'!$B$43 | F13: =F10*'Assumptions'!$B$43 | G13: =G10*'Assumptions'!$B$43 | H13: =H10*'Assumptions'!$B$43 | I13: =I10*'Assumptions'!$B$43 | ... Y13: =Y10*'Assumptions'!$B$43
A15: CUSTOMERS
A16: New customers — from email | B16: =B12*'Assumptions'!$B$47 | C16: =C12*'Assumptions'!$B$47 | D16: =D12*'Assumptions'!$B$47 | E16: =E12*'Assumptions'!$B$47 | F16: =F12*'Assumptions'!$B$47 | G16: =G12*'Assumptions'!$B$47 | H16: =H12*'Assumptions'!$B$47 | I16: =I12*'Assumptions'!$B$47 | ... Y16: =Y12*'Assumptions'!$B$47
A17: New customers — from postcard | B17: =B13*'Assumptions'!$B$48 | C17: =C13*'Assumptions'!$B$48 | D17: =D13*'Assumptions'!$B$48 | E17: =E13*'Assumptions'!$B$48 | F17: =F13*'Assumptions'!$B$48 | G17: =G13*'Assumptions'!$B$48 | H17: =H13*'Assumptions'!$B$48 | I17: =I13*'Assumptions'!$B$48 | ... Y17: =Y13*'Assumptions'!$B$48
A18: New customers, total | B18: =B16+B17 | C18: =C16+C17 | D18: =D16+D17 | E18: =E16+E17 | F18: =F16+F17 | G18: =G16+G17 | H18: =H16+H17 | I18: =I16+I17 | ... Y18: =Y16+Y17
A19: Active customers, end of month | B19: ='Assumptions'!$B$53*(1-'Assumptions'!$B$49)+B18 | C19: =B19*(1-'Assumptions'!$B$49)+C18 | D19: =C19*(1-'Assumptions'!$B$49)+D18 | E19: =D19*(1-'Assumptions'!$B$49)+E18 | F19: =E19*(1-'Assumptions'!$B$49)+F18 | G19: =F19*(1-'Assumptions'!$B$49)+G18 | H19: =G19*(1-'Assumptions'!$B$49)+H18 | I19: =H19*(1-'Assumptions'!$B$49)+I18 | J19: =I19*(1-'Assumptions'!$B$49)+J18 | ... Y19: =X19*(1-'Assumptions'!$B$49)+Y18
A21: REVENUE
A22: Setup fees | B22: =B18*'Assumptions'!$B$32 | C22: =C18*'Assumptions'!$B$32 | D22: =D18*'Assumptions'!$B$32 | E22: =E18*'Assumptions'!$B$32 | F22: =F18*'Assumptions'!$B$32 | G22: =G18*'Assumptions'!$B$32 | H22: =H18*'Assumptions'!$B$32 | I22: =I18*'Assumptions'!$B$32 | ... Y22: =Y18*'Assumptions'!$B$32
A23: Monthly fees | B23: =B19*'Assumptions'!$B$33 | C23: =C19*'Assumptions'!$B$33 | D23: =D19*'Assumptions'!$B$33 | E23: =E19*'Assumptions'!$B$33 | F23: =F19*'Assumptions'!$B$33 | G23: =G19*'Assumptions'!$B$33 | H23: =H19*'Assumptions'!$B$33 | I23: =I19*'Assumptions'!$B$33 | ... Y23: =Y19*'Assumptions'!$B$33
A24: Gross revenue | B24: =B22+B23 | C24: =C22+C23 | D24: =D22+D23 | E24: =E22+E23 | F24: =F22+F23 | G24: =G22+G23 | H24: =H22+H23 | I24: =I22+I23 | ... Y24: =Y22+Y23
A25: Less: Stripe fees | B25: =-((B22+B23)*'Assumptions'!$B$19+(B18+B19)*'Assumptions'!$B$20) | C25: =-((C22+C23)*'Assumptions'!$B$19+(C18+C19)*'Assumptions'!$B$20) | D25: =-((D22+D23)*'Assumptions'!$B$19+(D18+D19)*'Assumptions'!$B$20) | E25: =-((E22+E23)*'Assumptions'!$B$19+(E18+E19)*'Assumptions'!$B$20) | F25: =-((F22+F23)*'Assumptions'!$B$19+(F18+F19)*'Assumptions'!$B$20) | G25: =-((G22+G23)*'Assumptions'!$B$19+(G18+G19)*'Assumptions'!$B$20) | H25: =-((H22+H23)*'Assumptions'!$B$19+(H18+H19)*'Assumptions'!$B$20) | I25: =-((I22+I23)*'Assumptions'!$B$19+(I18+I19)*'Assumptions'!$B$20) | ... Y25: =-((Y22+Y23)*'Assumptions'!$B$19+(Y18+Y19)*'Assumptions'!$B$20)
A26: Net revenue | B26: =B24+B25 | C26: =C24+C25 | D26: =D24+D25 | E26: =E24+E25 | F26: =F24+F25 | G26: =G24+G25 | H26: =H24+H25 | I26: =I24+I25 | ... Y26: =Y24+Y25
A28: COSTS
A29: DataSkip lookups | B29: =-B8*'Assumptions'!$B$5 | C29: =-C8*'Assumptions'!$B$5 | D29: =-D8*'Assumptions'!$B$5 | E29: =-E8*'Assumptions'!$B$5 | F29: =-F8*'Assumptions'!$B$5 | G29: =-G8*'Assumptions'!$B$5 | H29: =-H8*'Assumptions'!$B$5 | I29: =-I8*'Assumptions'!$B$5 | ... Y29: =-Y8*'Assumptions'!$B$5
A30: Site builds | B30: =-B11*'Assumptions'!$B$11 | C30: =-C11*'Assumptions'!$B$11 | D30: =-D11*'Assumptions'!$B$11 | E30: =-E11*'Assumptions'!$B$11 | F30: =-F11*'Assumptions'!$B$11 | G30: =-G11*'Assumptions'!$B$11 | H30: =-H11*'Assumptions'!$B$11 | I30: =-I11*'Assumptions'!$B$11 | ... Y30: =-Y11*'Assumptions'!$B$11
A31: Postcards | B31: =-B13*'Assumptions'!$B$13 | C31: =-C13*'Assumptions'!$B$13 | D31: =-D13*'Assumptions'!$B$13 | E31: =-E13*'Assumptions'!$B$13 | F31: =-F13*'Assumptions'!$B$13 | G31: =-G13*'Assumptions'!$B$13 | H31: =-H13*'Assumptions'!$B$13 | I31: =-I13*'Assumptions'!$B$13 | ... Y31: =-Y13*'Assumptions'!$B$13
A32: Email sending | B32: =-B12*'Assumptions'!$B$12 | C32: =-C12*'Assumptions'!$B$12 | D32: =-D12*'Assumptions'!$B$12 | E32: =-E12*'Assumptions'!$B$12 | F32: =-F12*'Assumptions'!$B$12 | G32: =-G12*'Assumptions'!$B$12 | H32: =-H12*'Assumptions'!$B$12 | I32: =-I12*'Assumptions'!$B$12 | ... Y32: =-Y12*'Assumptions'!$B$12
A33: Hosting and tools | B33: =-'Assumptions'!$B$18 | C33: =-'Assumptions'!$B$18 | D33: =-'Assumptions'!$B$18 | E33: =-'Assumptions'!$B$18 | F33: =-'Assumptions'!$B$18 | G33: =-'Assumptions'!$B$18 | H33: =-'Assumptions'!$B$18 | I33: =-'Assumptions'!$B$18 | ... Y33: =-'Assumptions'!$B$18
A34: Total costs | B34: =SUM(B29:B33) | C34: =SUM(C29:C33) | D34: =SUM(D29:D33) | E34: =SUM(E29:E33) | F34: =SUM(F29:F33) | G34: =SUM(G29:G33) | H34: =SUM(H29:H33) | I34: =SUM(I29:I33) | ... Y34: =SUM(Y29:Y33)
A36: RESULT
A37: Profit / (loss) for the month | B37: =B26+B34 | C37: =C26+C34 | D37: =D26+D34 | E37: =E26+E34 | F37: =F26+F34 | G37: =G26+G34 | H37: =H26+H34 | I37: =I26+I34 | ... Y37: =Y26+Y34
A38: Cumulative cash position | B38: ='Assumptions'!$B$52+B37 | C38: =B38+C37 | D38: =C38+D37 | E38: =D38+E37 | F38: =E38+F37 | G38: =F38+G37 | H38: =G38+H37 | I38: =H38+I37 | J38: =I38+J37 | ... Y38: =X38+Y37
A39: Customer acquisition cost | B39: =IF(B18=0,0,-B34/B18) | C39: =IF(C18=0,0,-C34/C18) | D39: =IF(D18=0,0,-D34/D18) | E39: =IF(E18=0,0,-E34/E18) | F39: =IF(F18=0,0,-F34/F18) | G39: =IF(G18=0,0,-G34/G18) | H39: =IF(H18=0,0,-H34/H18) | I39: =IF(I18=0,0,-I34/I18) | ... Y39: =IF(Y18=0,0,-Y34/Y18)
A41: Note: 'Cumulative cash position' opens at the $283.51 already spent, so it must climb past zero before the business has paid for itself.

Sheet Scenarios
A1: Is this a profitable business?
A2: Year-one profit at different conversion rates, holding every other assumption fixed. Change the volume on the Assumptions sheet and these move.
A4: EMAIL CHANNEL | B4: Conversion | C4: Customers/yr | D4: Net revenue | E4: Total cost | F4: Year-one profit
A5: Pessimistic | B5: 0.0025 | C5: ='Assumptions'!$B$42*12*B5 | D5: =C5*('Assumptions'!$B$32+'Assumptions'!$B$33*6)*(1-'Assumptions'!$B$19)-C5*'Assumptions'!$B$20*7 | E5: =-('Assumptions'!$B$38*12*'Assumptions'!$B$5+'Assumptions'!$B$41*12*'Assumptions'!$B$11+'Assumptions'!$B$18*12) | F5: =D5+E5
A6: Low | B6: 0.005 | C6: ='Assumptions'!$B$42*12*B6 | D6: =C6*('Assumptions'!$B$32+'Assumptions'!$B$33*6)*(1-'Assumptions'!$B$19)-C6*'Assumptions'!$B$20*7 | E6: =-('Assumptions'!$B$38*12*'Assumptions'!$B$5+'Assumptions'!$B$41*12*'Assumptions'!$B$11+'Assumptions'!$B$18*12) | F6: =D6+E6
A7: Base case | B7: 0.01 | C7: ='Assumptions'!$B$42*12*B7 | D7: =C7*('Assumptions'!$B$32+'Assumptions'!$B$33*6)*(1-'Assumptions'!$B$19)-C7*'Assumptions'!$B$20*7 | E7: =-('Assumptions'!$B$38*12*'Assumptions'!$B$5+'Assumptions'!$B$41*12*'Assumptions'!$B$11+'Assumptions'!$B$18*12) | F7: =D7+E7
A8: Good | B8: 0.02 | C8: ='Assumptions'!$B$42*12*B8 | D8: =C8*('Assumptions'!$B$32+'Assumptions'!$B$33*6)*(1-'Assumptions'!$B$19)-C8*'Assumptions'!$B$20*7 | E8: =-('Assumptions'!$B$38*12*'Assumptions'!$B$5+'Assumptions'!$B$41*12*'Assumptions'!$B$11+'Assumptions'!$B$18*12) | F8: =D8+E8
A9: Strong | B9: 0.03 | C9: ='Assumptions'!$B$42*12*B9 | D9: =C9*('Assumptions'!$B$32+'Assumptions'!$B$33*6)*(1-'Assumptions'!$B$19)-C9*'Assumptions'!$B$20*7 | E9: =-('Assumptions'!$B$38*12*'Assumptions'!$B$5+'Assumptions'!$B$41*12*'Assumptions'!$B$11+'Assumptions'!$B$18*12) | F9: =D9+E9
A10: Exceptional | B10: 0.05 | C10: ='Assumptions'!$B$42*12*B10 | D10: =C10*('Assumptions'!$B$32+'Assumptions'!$B$33*6)*(1-'Assumptions'!$B$19)-C10*'Assumptions'!$B$20*7 | E10: =-('Assumptions'!$B$38*12*'Assumptions'!$B$5+'Assumptions'!$B$41*12*'Assumptions'!$B$11+'Assumptions'!$B$18*12) | F10: =D10+E10
A13: Revenue counts the setup fee plus an average of 6 monthly payments, because customers arrive through the year rather than on day one.
A16: THE TWO CHANNELS, PER LEAD | B16: Email | C16: Postcard
A17: Cost to find and reach one lead | B17: ='Assumptions'!$B$14 | C17: ='Assumptions'!$B$15
A18: Break-even conversion rate | B18: ='Assumptions'!$B$59 | C18: ='Assumptions'!$B$60
A19: One sale needed per … leads | B19: =1/'Assumptions'!$B$59 | C19: =1/'Assumptions'!$B$60
A20: Assumed conversion | B20: ='Assumptions'!$B$47 | C20: ='Assumptions'!$B$48
A21: Profit per 1,000 leads reached | B21: =1000*('Assumptions'!$B$47*'Assumptions'!$B$57-'Assumptions'!$B$14) | C21: =1000*('Assumptions'!$B$48*'Assumptions'!$B$57-'Assumptions'!$B$15)
A24: WHAT IT COSTS TO WORK THE WHOLE LIST
A25: Qualified leads never checked | B25: =31487
A26: DataSkip to check all of them | B26: =-31487*'Assumptions'!$B$5
A27: Emails that would yield | B27: =31487*'Assumptions'!$B$6
A28: Sites to build for them | B28: =-31487*'Assumptions'!$B$6*'Assumptions'!$B$11
A29: Total to work the entire list by email | B29: =-31487*('Assumptions'!$B$5+'Assumptions'!$B$6*'Assumptions'!$B$11)
A30: Customers at the base-case rate | B30: =31487*'Assumptions'!$B$6*'Assumptions'!$B$47
A31: Year-one net revenue from them | B31: =31487*'Assumptions'!$B$6*'Assumptions'!$B$47*'Assumptions'!$B$57
A32: Net result | B32: =31487*'Assumptions'!$B$6*'Assumptions'!$B$47*'Assumptions'!$B$57-31487*('Assumptions'!$B$5+'Assumptions'!$B$6*'Assumptions'!$B$11)

Sheet Price vs conversion
A1: How low can the price go?
A2: Monthly fee held at $50 throughout. Only the one-off setup fee changes.
A3: Cost to find, build and email one lead is on the Assumptions sheet (B14). Everything here is driven by it.
A5: BREAK-EVEN AT EACH SETUP PRICE | B5: Customer stays 12 months | E5: Cash in your hand this month
A6: Setup fee | B6: Year-one net | C6: B/E conversion | D6: 1 sale in … | E6: Cash on 1st sale | F6: B/E conversion | G6: 1 sale in …
A7: 0 | B7: =(A7+'Assumptions'!$C$24*12)*(1-'Assumptions'!$B$19)-'Assumptions'!$B$20*13 | C7: ='Assumptions'!$B$14/B7 | D7: =B7/'Assumptions'!$B$14 | E7: =(A7+'Assumptions'!$C$24)*(1-'Assumptions'!$B$19)-'Assumptions'!$B$20*2 | F7: ='Assumptions'!$B$14/E7 | G7: =E7/'Assumptions'!$B$14
A8: 50 | B8: =(A8+'Assumptions'!$C$24*12)*(1-'Assumptions'!$B$19)-'Assumptions'!$B$20*13 | C8: ='Assumptions'!$B$14/B8 | D8: =B8/'Assumptions'!$B$14 | E8: =(A8+'Assumptions'!$C$24)*(1-'Assumptions'!$B$19)-'Assumptions'!$B$20*2 | F8: ='Assumptions'!$B$14/E8 | G8: =E8/'Assumptions'!$B$14
A9: 100 | B9: =(A9+'Assumptions'!$C$24*12)*(1-'Assumptions'!$B$19)-'Assumptions'!$B$20*13 | C9: ='Assumptions'!$B$14/B9 | D9: =B9/'Assumptions'!$B$14 | E9: =(A9+'Assumptions'!$C$24)*(1-'Assumptions'!$B$19)-'Assumptions'!$B$20*2 | F9: ='Assumptions'!$B$14/E9 | G9: =E9/'Assumptions'!$B$14
A10: 250 | B10: =(A10+'Assumptions'!$C$24*12)*(1-'Assumptions'!$B$19)-'Assumptions'!$B$20*13 | C10: ='Assumptions'!$B$14/B10 | D10: =B10/'Assumptions'!$B$14 | E10: =(A10+'Assumptions'!$C$24)*(1-'Assumptions'!$B$19)-'Assumptions'!$B$20*2 | F10: ='Assumptions'!$B$14/E10 | G10: =E10/'Assumptions'!$B$14
A11: 395 | B11: =(A11+'Assumptions'!$C$24*12)*(1-'Assumptions'!$B$19)-'Assumptions'!$B$20*13 | C11: ='Assumptions'!$B$14/B11 | D11: =B11/'Assumptions'!$B$14 | E11: =(A11+'Assumptions'!$C$24)*(1-'Assumptions'!$B$19)-'Assumptions'!$B$20*2 | F11: ='Assumptions'!$B$14/E11 | G11: =E11/'Assumptions'!$B$14
A12: 500 | B12: =(A12+'Assumptions'!$C$24*12)*(1-'Assumptions'!$B$19)-'Assumptions'!$B$20*13 | C12: ='Assumptions'!$B$14/B12 | D12: =B12/'Assumptions'!$B$14 | E12: =(A12+'Assumptions'!$C$24)*(1-'Assumptions'!$B$19)-'Assumptions'!$B$20*2 | F12: ='Assumptions'!$B$14/E12 | G12: =E12/'Assumptions'!$B$14
A13: 750 | B13: =(A13+'Assumptions'!$C$24*12)*(1-'Assumptions'!$B$19)-'Assumptions'!$B$20*13 | C13: ='Assumptions'!$B$14/B13 | D13: =B13/'Assumptions'!$B$14 | E13: =(A13+'Assumptions'!$C$24)*(1-'Assumptions'!$B$19)-'Assumptions'!$B$20*2 | F13: ='Assumptions'!$B$14/E13 | G13: =E13/'Assumptions'!$B$14
A14: 1000 | B14: =(A14+'Assumptions'!$C$24*12)*(1-'Assumptions'!$B$19)-'Assumptions'!$B$20*13 | C14: ='Assumptions'!$B$14/B14 | D14: =B14/'Assumptions'!$B$14 | E14: =(A14+'Assumptions'!$C$24)*(1-'Assumptions'!$B$19)-'Assumptions'!$B$20*2 | F14: ='Assumptions'!$B$14/E14 | G14: =E14/'Assumptions'!$B$14
A15: 1500 | B15: =(A15+'Assumptions'!$C$24*12)*(1-'Assumptions'!$B$19)-'Assumptions'!$B$20*13 | C15: ='Assumptions'!$B$14/B15 | D15: =B15/'Assumptions'!$B$14 | E15: =(A15+'Assumptions'!$C$24)*(1-'Assumptions'!$B$19)-'Assumptions'!$B$20*2 | F15: ='Assumptions'!$B$14/E15 | G15: =E15/'Assumptions'!$B$14
A16: Today's Starter price is $750. The row above it, $500, and $250 below it, are the ones worth thinking about.
A18: WHAT DROPPING THE SETUP FEE COSTS YOU
A19: How much better a $0-setup offer must convert, to match $750 + $50/mo
A20: …if every customer stays a full 12 months | B20: =B14/B7
A21: …measured on cash received this month | B21: =E14/E7
A22: 2.26x is plausible for a big price cut. 16x is not. That gap is the whole argument.
A25: CASH IN YOUR HAND, PER 1,000 LEADS EMAILED
A26: Setup fee ↓ Conversion → | B26: 0.001 | C26: 0.0025 | D26: 0.005 | E26: 0.01 | F26: 0.02 | G26: 0.03 | H26: 0.05
A27: =A7 | B27: =1000*(B$26*$E7-'Assumptions'!$B$14) | C27: =1000*(C$26*$E7-'Assumptions'!$B$14) | D27: =1000*(D$26*$E7-'Assumptions'!$B$14) | E27: =1000*(E$26*$E7-'Assumptions'!$B$14) | F27: =1000*(F$26*$E7-'Assumptions'!$B$14) | G27: =1000*(G$26*$E7-'Assumptions'!$B$14) | H27: =1000*(H$26*$E7-'Assumptions'!$B$14)
A28: =A8 | B28: =1000*(B$26*$E8-'Assumptions'!$B$14) | C28: =1000*(C$26*$E8-'Assumptions'!$B$14) | D28: =1000*(D$26*$E8-'Assumptions'!$B$14) | E28: =1000*(E$26*$E8-'Assumptions'!$B$14) | F28: =1000*(F$26*$E8-'Assumptions'!$B$14) | G28: =1000*(G$26*$E8-'Assumptions'!$B$14) | H28: =1000*(H$26*$E8-'Assumptions'!$B$14)
A29: =A9 | B29: =1000*(B$26*$E9-'Assumptions'!$B$14) | C29: =1000*(C$26*$E9-'Assumptions'!$B$14) | D29: =1000*(D$26*$E9-'Assumptions'!$B$14) | E29: =1000*(E$26*$E9-'Assumptions'!$B$14) | F29: =1000*(F$26*$E9-'Assumptions'!$B$14) | G29: =1000*(G$26*$E9-'Assumptions'!$B$14) | H29: =1000*(H$26*$E9-'Assumptions'!$B$14)
A30: =A10 | B30: =1000*(B$26*$E10-'Assumptions'!$B$14) | C30: =1000*(C$26*$E10-'Assumptions'!$B$14) | D30: =1000*(D$26*$E10-'Assumptions'!$B$14) | E30: =1000*(E$26*$E10-'Assumptions'!$B$14) | F30: =1000*(F$26*$E10-'Assumptions'!$B$14) | G30: =1000*(G$26*$E10-'Assumptions'!$B$14) | H30: =1000*(H$26*$E10-'Assumptions'!$B$14)
A31: =A11 | B31: =1000*(B$26*$E11-'Assumptions'!$B$14) | C31: =1000*(C$26*$E11-'Assumptions'!$B$14) | D31: =1000*(D$26*$E11-'Assumptions'!$B$14) | E31: =1000*(E$26*$E11-'Assumptions'!$B$14) | F31: =1000*(F$26*$E11-'Assumptions'!$B$14) | G31: =1000*(G$26*$E11-'Assumptions'!$B$14) | H31: =1000*(H$26*$E11-'Assumptions'!$B$14)
A32: =A12 | B32: =1000*(B$26*$E12-'Assumptions'!$B$14) | C32: =1000*(C$26*$E12-'Assumptions'!$B$14) | D32: =1000*(D$26*$E12-'Assumptions'!$B$14) | E32: =1000*(E$26*$E12-'Assumptions'!$B$14) | F32: =1000*(F$26*$E12-'Assumptions'!$B$14) | G32: =1000*(G$26*$E12-'Assumptions'!$B$14) | H32: =1000*(H$26*$E12-'Assumptions'!$B$14)
A33: =A13 | B33: =1000*(B$26*$E13-'Assumptions'!$B$14) | C33: =1000*(C$26*$E13-'Assumptions'!$B$14) | D33: =1000*(D$26*$E13-'Assumptions'!$B$14) | E33: =1000*(E$26*$E13-'Assumptions'!$B$14) | F33: =1000*(F$26*$E13-'Assumptions'!$B$14) | G33: =1000*(G$26*$E13-'Assumptions'!$B$14) | H33: =1000*(H$26*$E13-'Assumptions'!$B$14)
A34: =A14 | B34: =1000*(B$26*$E14-'Assumptions'!$B$14) | C34: =1000*(C$26*$E14-'Assumptions'!$B$14) | D34: =1000*(D$26*$E14-'Assumptions'!$B$14) | E34: =1000*(E$26*$E14-'Assumptions'!$B$14) | F34: =1000*(F$26*$E14-'Assumptions'!$B$14) | G34: =1000*(G$26*$E14-'Assumptions'!$B$14) | H34: =1000*(H$26*$E14-'Assumptions'!$B$14)
A35: =A15 | B35: =1000*(B$26*$E15-'Assumptions'!$B$14) | C35: =1000*(C$26*$E15-'Assumptions'!$B$14) | D35: =1000*(D$26*$E15-'Assumptions'!$B$14) | E35: =1000*(E$26*$E15-'Assumptions'!$B$14) | F35: =1000*(F$26*$E15-'Assumptions'!$B$14) | G35: =1000*(G$26*$E15-'Assumptions'!$B$14) | H35: =1000*(H$26*$E15-'Assumptions'!$B$14)
A36: Each cell is the cash you would hold this month after emailing 1,000 leads, at that price and that conversion rate.
A37: Red means you spent more finding and building than the sale brought back.
A40: THE ACTUAL FLOOR
A41: Lowest setup fee that still breaks even, if the customer stays 12 months | B41: Conversion | C41: Needed, year-one net | D41: Required setup fee
B42: 0.0005 | C42: ='Assumptions'!$B$14/B42 | D42: =MAX(0,(C42+'Assumptions'!$B$20*13)/(1-'Assumptions'!$B$19)-'Assumptions'!$C$24*12)
B43: 0.001 | C43: ='Assumptions'!$B$14/B43 | D43: =MAX(0,(C43+'Assumptions'!$B$20*13)/(1-'Assumptions'!$B$19)-'Assumptions'!$C$24*12)
B44: 0.0025 | C44: ='Assumptions'!$B$14/B44 | D44: =MAX(0,(C44+'Assumptions'!$B$20*13)/(1-'Assumptions'!$B$19)-'Assumptions'!$C$24*12)
B45: 0.005 | C45: ='Assumptions'!$B$14/B45 | D45: =MAX(0,(C45+'Assumptions'!$B$20*13)/(1-'Assumptions'!$B$19)-'Assumptions'!$C$24*12)
B46: 0.01 | C46: ='Assumptions'!$B$14/B46 | D46: =MAX(0,(C46+'Assumptions'!$B$20*13)/(1-'Assumptions'!$B$19)-'Assumptions'!$C$24*12)
...
